<?xml version="1.0"?>
<robot name="tb3_sara" xmlns:xacro="http://ros.org/wiki/xacro">

    <xacro:arg name="arm_id_1" default="sara_1" />
    <xacro:arg name="arm_id_2" default="sara_2" />

    <!--<xacro:include filename="$(find tb3mm_6dof)/urdf/sara.gazebo.xacro"/>-->
    <xacro:include filename="$(find tb3mm_6dof)/urdf/sara.transmission.xacro"/>
    <xacro:include filename="$(find turtlebot3_description)/urdf/common_properties.xacro"/>
    <!--<xacro:include filename="$(find tb3mm_6dof)/urdf/tb3_for_om_d435.gazebo.xacro"/> -->
    <!--<xacro:include filename="$(find realsense2_description)/urdf/_d435.urdf.xacro" />-->
    <!--<xacro:include filename="$(find tb3mm_6dof)/urdf/tb3_for_om_d435.urdf.xacro"/> -->
    <!--<xacro:include filename="$(find tb3mm_6dof)/urdf/sara.urdf.xacro"/>-->
    <!--<xacro:include filename="$(find turtlebot3_description)/urdf/turtlebot3_waffle_pi_for_open_manipulator.urdf.xacro"/>-->

<link name="base">
  <visual>
    <origin xyz="0 0 0" rpy="0 0 0"/>
    <geometry>
      <box size="0.5 0.5 0.2"/>
    </geometry>
    <material name="White">
      <color rgba="1.0 1.0 1.0 1.0"/>
    </material>
  </visual>
  <collision>
    <origin xyz="0 0 0" rpy="0 0 0"/>
    <geometry>
      <box size="0.5 0.5 0.2"/>
    </geometry>
  </collision>
  <inertial>
    <origin xyz="0 0 0" rpy="0 0 0"/>
    <mass value="5.0"/>
    <inertia ixx="0.01" ixy="0.0" ixz="0.0" iyy="0.01" iyz="0.0" izz="0.01"/>
  </inertial>
</link>

<!-- sara_1 arm을 base에 고정 -->
<joint name="sara_1_base_joint" type="fixed">
  <parent link="base"/>
  <child link="sara_1_link1"/>
  <origin xyz="0.1 0.0 0.5" rpy="0 0 0"/>
</joint>

<!-- sara_2 arm을 base에 고정 -->
<joint name="sara_2_base_joint" type="fixed">
  <parent link="base"/>
  <child link="sara_2_link1"/>
  <origin xyz="-0.1 0.0 0.5" rpy="0 0 0"/>
</joint>


<joint name="base_to_world" type="fixed">
  <parent link="world"/>
  <child link="base"/>
  <origin xyz="0 0 0" rpy="0 0 0"/>
</joint>

     <!-- Link 1 -->
  <link name="sara_1_link1" >
    <visual>
      <origin xyz="0 0 0" rpy="0 0 0"/>
      <geometry>
        <mesh filename="package://open_manipulator_6dof_description/meshes/chain_link1.stl" scale="0.001 0.001 0.001"/>
      </geometry>
      <material name="grey"/>
    </visual>

    <collision>
      <origin xyz="0 0 0" rpy="0 0 0"/>
      <geometry>
        <mesh filename="package://open_manipulator_6dof_description/meshes/chain_link1.stl" scale="0.001 0.001 0.001"/>
      </geometry>
    </collision>

    <inertial>
      <origin xyz="3.0876154e-04 0.0000000e+00 -1.2176461e-04" />
      <mass value="7.9119962e-02" />
      <inertia ixx="1.2505234e-05" ixy="0.0" ixz="-1.7855208e-07"
               iyy="2.1898364e-05" iyz="0.0"
               izz="1.9267361e-05" />
    </inertial>
  </link>

  <!-- Joint 1 -->
  <joint name="sara_1_joint1" type="revolute">
    <parent link="sara_1_link1"/>
    <child link="sara_1_link2"/>
    <origin xyz="0.012 0.0 0.017" rpy="0 0 0"/>
    <axis xyz="0 0 1"/>
    <limit velocity="4.8" effort="1" lower="${-pi*0.9}" upper="${pi*0.9}" />
  </joint>

    <!--  Link 2 -->
  <link name="sara_1_link2">
    <visual>
      <origin xyz="0 0 0.019" rpy="0 0 0"/>
      <geometry>
        <mesh filename="package://open_manipulator_6dof_description/meshes/chain_link2.stl" scale="0.001 0.001 0.001"/>
      </geometry>
      <material name="grey"/>
    </visual>

    <collision>
      <origin xyz="0 0 0.019" rpy="0 0 0"/>
      <geometry>
        <mesh filename="package://open_manipulator_6dof_description/meshes/chain_link2.stl" scale="0.001 0.001 0.001"/>
      </geometry>
    </collision>

    <inertial>
      <origin xyz="-3.0184870e-04 5.4043684e-04 ${0.018 + 2.9433464e-02}" />
      <mass value="9.8406837e-02" />
      <inertia ixx="3.4543422e-05" ixy="-1.6031095e-08" ixz="-3.8375155e-07"
               iyy="3.2689329e-05" iyz="2.8511935e-08"
               izz="1.8850320e-05" />
    </inertial>
  </link>

   <!--  Joint 2 -->
  <joint name="sara_1_joint2" type="revolute">
    <parent link="sara_1_link2"/>
    <child link="sara_1_link3"/>
    <origin xyz="0.0 0.0 0.0595" rpy="0 0 0"/>
    <axis xyz="0 1 0"/>
    <limit velocity="4.8" effort="1" lower="${-pi*0.65}" upper="${pi*0.67}" />
  </joint>

  <!--  Link 3 -->
  <link name="sara_1_link3">
    <visual>
      <origin xyz="0 0 0" rpy="0 0 0"/>
      <geometry>
        <mesh filename="package://open_manipulator_6dof_description/meshes/chain_link3.stl" scale="0.001 0.001 0.001"/>
      </geometry>
      <material name="grey"/>
    </visual>

    <collision>
      <origin xyz="0 0 0" rpy="0 0 0"/>
      <geometry>
        <mesh filename="package://open_manipulator_6dof_description/meshes/chain_link3.stl" scale="0.001 0.001 0.001"/>
      </geometry>
    </collision>

    <inertial>
      <origin xyz="0 0 0" />
      <mass value="0.131" />
      <inertia ixx="0.1" ixy="0.0" ixz="0.0"
               iyy="0.1" iyz="0.0"
               izz="0.1" />
    </inertial>
  </link>

  <!--  Joint 3 -->
  <joint name="sara_1_joint3" type="revolute">
    <parent link="sara_1_link3"/>
    <child link="sara_1_link4"/>
    <origin xyz="0.0 0 0.124" rpy="0 0 0"/>
    <axis xyz="0 1 0"/>
    <limit velocity="4.8" effort="1" lower="${-pi*0.60}" upper="${pi*0.68}" />
  </joint>

<!--  Link 4 -->
  <link name="sara_1_link4">
    <visual>
      <origin xyz="0 0 0" rpy="0 0 0"/>
      <geometry>
        <mesh filename="package://open_manipulator_6dof_description/meshes/chain_link4.stl" scale="0.001 0.001 0.001"/>
      </geometry>
      <material name="grey"/>
    </visual>

    <collision>
      <origin xyz="0 0 0" rpy="0 0 0"/>
      <geometry>
        <mesh filename="package://open_manipulator_6dof_description/meshes/chain_link4.stl" scale="0.001 0.001 0.001"/>
      </geometry>
    </collision>

    <inertial>
      <origin xyz="0 0 0" />
      <mass value="0.098" />
      <inertia ixx="0.1" ixy="0.0" ixz="0.0"
               iyy="0.1" iyz="0.0"
               izz="0.1" />
    </inertial>
  </link>

  <!--  Joint 4 -->
  <joint name="sara_1_joint4" type="revolute">
    <parent link="sara_1_link4"/>
    <child link="sara_1_link5"/>
    <origin xyz="0.0 0.0 0.045" rpy="0 0 0"/>
    <axis xyz="0 0 1"/>
    <limit velocity="4.8" effort="1" lower="${-pi*0.9}" upper="${pi*0.9}" />
  </joint>

  <!--  Link 5 -->
  <link name="sara_1_link5">
    <visual>
      <origin xyz="0 0 0.019" rpy="0 0 0"/>
      <geometry>
        <mesh filename="package://open_manipulator_6dof_description/meshes/chain_link5.stl" scale="0.001 0.001 0.001"/>
      </geometry>
      <material name="grey"/>
    </visual>

    <collision>
      <origin xyz="0 0 0.019" rpy="0 0 0"/>
      <geometry>
        <mesh filename="package://open_manipulator_6dof_description/meshes/chain_link5.stl" scale="0.001 0.001 0.001"/>
      </geometry>
    </collision>

    <inertial>
      <origin xyz="0 0 0" />
      <mass value="0.098" />
      <inertia ixx="0.1" ixy="0.0" ixz="0.0"
               iyy="0.1" iyz="0.0"
               izz="0.1" />
    </inertial>
  </link>

   <!--  Joint 5 -->
  <joint name="sara_1_joint5" type="revolute">
    <parent link="sara_1_link5"/>
    <child link="sara_1_link6"/>
    <origin xyz="0.0 0.0 0.0595" rpy="0 0 0"/>
    <axis xyz="0 1 0"/>
    <limit velocity="4.8" effort="1" lower="${-pi*0.63}" upper="${pi*0.67}" />
  </joint>

  <!--  Link 6 -->
  <link name="sara_1_link6">
    <visual>
      <origin xyz="0 0 0.0" rpy="0 0 0"/>
      <geometry>
        <mesh filename="package://open_manipulator_6dof_description/meshes/chain_link6.stl" scale="0.001 0.001 0.001"/>
      </geometry>
      <material name="grey"/>
    </visual>

    <collision>
      <origin xyz="0 0 0.0" rpy="0 0 0"/>
      <geometry>
        <mesh filename="package://open_manipulator_6dof_description/meshes/chain_link6.stl" scale="0.001 0.001 0.001"/>
      </geometry>
    </collision>

    <inertial>
      <origin xyz="0 0 0" />
      <mass value="0.033" />
      <inertia ixx="0.1" ixy="0.0" ixz="0.0"
               iyy="0.1" iyz="0.0"
               izz="0.1" />
    </inertial>

     <inertial>
      <origin xyz="4.4206755e-02 3.6839985e-07 8.9142216e-03" />
      <mass value="1.4327573e-01" />
      <inertia ixx="8.0870749e-05" ixy="0.0" ixz="-1.0157896e-06"
               iyy="7.5980465e-05" iyz="0.0"
               izz="9.3127351e-05" />
    </inertial>
  </link>

<!--  Joint 6 -->
  <joint name="sara_1_joint6" type="revolute">
    <parent link="sara_1_link6"/>
    <child link="sara_1_link7"/>
    <origin xyz="0.0 0.0 0.0475" rpy="0 0 0"/>
    <axis xyz="0 0 1"/>
    <limit velocity="4.8" effort="1" lower="${-pi*0.9}" upper="${pi*0.9}" />
  </joint>

<!--  Link 7 -->
  <link name="sara_1_link7">
    <visual>
      <origin xyz="0 0 0.0" rpy="0 0 0"/>
      <geometry>
        <mesh filename="package://open_manipulator_6dof_description/meshes/chain_link7.stl" scale="0.001 0.001 0.001"/>
      </geometry>
      <!-- <material name="grey"/> -->
    </visual>

    <collision>
      <origin xyz="0 0 0.0" rpy="0 0 0"/>
      <geometry>
        <mesh filename="package://open_manipulator_6dof_description/meshes/chain_link7.stl" scale="0.001 0.001 0.001"/>
      </geometry>
    </collision>

    <inertial>
      <origin xyz="4.4206755e-02 3.6839985e-07 8.9142216e-03" />
      <mass value="1.4327573e-01" />
      <inertia ixx="8.0870749e-05" ixy="0.0" ixz="-1.0157896e-06"
               iyy="7.5980465e-05" iyz="0.0"
               izz="9.3127351e-05" />
    </inertial>
  </link>

  <!--  Gripper link -->
  <link name="sara_1_gripper_link">
    <visual>
      <origin xyz="0.0 0.0 0" rpy="0 0 0"/>
      <geometry>
        <mesh filename="package://open_manipulator_6dof_description/meshes/chain_link_grip_l.stl" scale="0.001 0.001 0.001"/>
      </geometry>
      <material name="grey"/>
    </visual>

    <collision>
      <origin xyz="0.0 0.0 0" rpy="0 0 0"/>
      <geometry>
        <mesh filename="package://open_manipulator_6dof_description/meshes/chain_link_grip_l.stl" scale="0.001 0.001 0.001"/>
      </geometry>
    </collision>

    <inertial>
      <origin xyz="0 0 0" />
      <mass value="1.0e-03" />
      <inertia ixx="1.0e-03" ixy="0.0" ixz="0.0"
               iyy="1.0e-03" iyz="0.0"
               izz="1.0e-03" />
    </inertial>
  </link>

  <!--  Gripper joint -->
  <joint name="sara_1_gripper" type="prismatic">
    <parent link="sara_1_link7"/>
    <child link="sara_1_gripper_link"/>
    <origin xyz="0.0 0.021 0.0707" rpy="0 0 0"/>
    <axis xyz="0 1 0"/>
    <limit velocity="4.8" effort="1" lower="-0.010" upper="0.019" />
  </joint>

  <!--  Gripper link sub -->
  <link name="sara_1_gripper_link_sub">
    <visual>
      <origin xyz="0.0 -0.0 0" rpy="0 0 0"/>
      <geometry>
        <mesh filename="package://open_manipulator_6dof_description/meshes/chain_link_grip_r.stl" scale="0.001 0.001 0.001"/>
      </geometry>
      <material name="grey"/>
    </visual>

    <collision>
      <origin xyz="0.0 -0.0 0" rpy="0 0 0"/>
      <geometry>
        <mesh filename="package://open_manipulator_6dof_description/meshes/chain_link_grip_r.stl" scale="0.001 0.001 0.001"/>
      </geometry>
    </collision>

    <inertial>
      <origin xyz="0 0 0" />
      <mass value="1.0e-03" />
      <inertia ixx="1.0e-03" ixy="0.0" ixz="0.0"
               iyy="1.0e-03" iyz="0.0"
               izz="1.0e-03" />
    </inertial>
  </link>

  <!--  Gripper joint sub -->
  <joint name="sara_1_gripper_sub" type="prismatic">
    <parent link="sara_1_link7"/>
    <child link="sara_1_gripper_link_sub"/>
    <origin xyz="0.0 -0.021 0.0707" rpy="0 0 0"/>
    <axis xyz="0 -1 0"/>
    <limit velocity="4.8" effort="1" lower="-0.010" upper="0.019" />
    <mimic joint="sara_1_gripper" multiplier="1"/>
  </joint>

  <!-- end effector joint -->
  <joint name="sara_1_end_effector_joint" type="fixed">
    <origin xyz="0.0 0.0 0.115" rpy="0 0 0"/>
    <parent link="sara_1_link7"/>
    <child link="sara_1_end_effector_link"/>
  </joint>

  <!-- end effector link -->
  <link name="sara_1_end_effector_link">
    <visual>
      <origin xyz="0 0 0" rpy="0 0 0"/>
      <geometry>
        <box size="0.01 0.01 0.01" />
      </geometry>
      <material name="red"/>
     </visual>

    <inertial>
      <origin xyz="0 0 0" />
      <mass value="1.0e-03" />
      <inertia ixx="1.0e-03" ixy="0.0" ixz="0.0"
               iyy="1.0e-03" iyz="0.0"
               izz="1.0e-03" />
    </inertial>
  </link>


 <!-- Link 1 -->
  <link name="sara_2_link1">
    <visual>
      <origin xyz="0 0 0" rpy="0 0 0"/>
      <geometry>
        <mesh filename="package://open_manipulator_6dof_description/meshes/chain_link1.stl" scale="0.001 0.001 0.001"/>
      </geometry>
      <material name="grey"/>
    </visual>

    <collision>
      <origin xyz="0 0 0" rpy="0 0 0"/>
      <geometry>
        <mesh filename="package://open_manipulator_6dof_description/meshes/chain_link1.stl" scale="0.001 0.001 0.001"/>
      </geometry>
    </collision>

    <inertial>
      <origin xyz="3.0876154e-04 0.0000000e+00 -1.2176461e-04" />
      <mass value="7.9119962e-02" />
      <inertia ixx="1.2505234e-05" ixy="0.0" ixz="-1.7855208e-07"
               iyy="2.1898364e-05" iyz="0.0"
               izz="1.9267361e-05" />
    </inertial>
  </link>

  <!-- Joint 1 -->
  <joint name="sara_2_joint1" type="revolute">
    <parent link="sara_2_link1"/>
    <child link="sara_2_link2"/>
    <origin xyz="0.012 0.0 0.017" rpy="0 0 0"/>
    <axis xyz="0 0 1"/>
    <limit velocity="4.8" effort="1" lower="${-pi*0.9}" upper="${pi*0.9}" />
  </joint>

    <!--  Link 2 -->
  <link name="sara_2_link2">
    <visual>
      <origin xyz="0 0 0.019" rpy="0 0 0"/>
      <geometry>
        <mesh filename="package://open_manipulator_6dof_description/meshes/chain_link2.stl" scale="0.001 0.001 0.001"/>
      </geometry>
      <material name="grey"/>
    </visual>

    <collision>
      <origin xyz="0 0 0.019" rpy="0 0 0"/>
      <geometry>
        <mesh filename="package://open_manipulator_6dof_description/meshes/chain_link2.stl" scale="0.001 0.001 0.001"/>
      </geometry>
    </collision>

    <inertial>
      <origin xyz="-3.0184870e-04 5.4043684e-04 ${0.018 + 2.9433464e-02}" />
      <mass value="9.8406837e-02" />
      <inertia ixx="3.4543422e-05" ixy="-1.6031095e-08" ixz="-3.8375155e-07"
               iyy="3.2689329e-05" iyz="2.8511935e-08"
               izz="1.8850320e-05" />
    </inertial>
  </link>

   <!--  Joint 2 -->
  <joint name="sara_2_joint2" type="revolute">
    <parent link="sara_2_link2"/>
    <child link="sara_2_link3"/>
    <origin xyz="0.0 0.0 0.0595" rpy="0 0 0"/>
    <axis xyz="0 1 0"/>
    <limit velocity="4.8" effort="1" lower="${-pi*0.65}" upper="${pi*0.67}" />
  </joint>

  <!--  Link 3 -->
  <link name="sara_2_link3">
    <visual>
      <origin xyz="0 0 0" rpy="0 0 0"/>
      <geometry>
        <mesh filename="package://open_manipulator_6dof_description/meshes/chain_link3.stl" scale="0.001 0.001 0.001"/>
      </geometry>
      <material name="grey"/>
    </visual>

    <collision>
      <origin xyz="0 0 0" rpy="0 0 0"/>
      <geometry>
        <mesh filename="package://open_manipulator_6dof_description/meshes/chain_link3.stl" scale="0.001 0.001 0.001"/>
      </geometry>
    </collision>

    <inertial>
      <origin xyz="0 0 0" />
      <mass value="0.131" />
      <inertia ixx="0.1" ixy="0.0" ixz="0.0"
               iyy="0.1" iyz="0.0"
               izz="0.1" />
    </inertial>
  </link>

  <!--  Joint 3 -->
  <joint name="sara_2_joint3" type="revolute">
    <parent link="sara_2_link3"/>
    <child link="sara_2_link4"/>
    <origin xyz="0.0 0 0.124" rpy="0 0 0"/>
    <axis xyz="0 1 0"/>
    <limit velocity="4.8" effort="1" lower="${-pi*0.60}" upper="${pi*0.68}" />
  </joint>

<!--  Link 4 -->
  <link name="sara_2_link4">
    <visual>
      <origin xyz="0 0 0" rpy="0 0 0"/>
      <geometry>
        <mesh filename="package://open_manipulator_6dof_description/meshes/chain_link4.stl" scale="0.001 0.001 0.001"/>
      </geometry>
      <material name="grey"/>
    </visual>

    <collision>
      <origin xyz="0 0 0" rpy="0 0 0"/>
      <geometry>
        <mesh filename="package://open_manipulator_6dof_description/meshes/chain_link4.stl" scale="0.001 0.001 0.001"/>
      </geometry>
    </collision>

    <inertial>
      <origin xyz="0 0 0" />
      <mass value="0.098" />
      <inertia ixx="0.1" ixy="0.0" ixz="0.0"
               iyy="0.1" iyz="0.0"
               izz="0.1" />
    </inertial>
  </link>

  <!--  Joint 4 -->
  <joint name="sara_2_joint4" type="revolute">
    <parent link="sara_2_link4"/>
    <child link="sara_2_link5"/>
    <origin xyz="0.0 0.0 0.045" rpy="0 0 0"/>
    <axis xyz="0 0 1"/>
    <limit velocity="4.8" effort="1" lower="${-pi*0.9}" upper="${pi*0.9}" />
  </joint>

  <!--  Link 5 -->
  <link name="sara_2_link5">
    <visual>
      <origin xyz="0 0 0.019" rpy="0 0 0"/>
      <geometry>
        <mesh filename="package://open_manipulator_6dof_description/meshes/chain_link5.stl" scale="0.001 0.001 0.001"/>
      </geometry>
      <material name="grey"/>
    </visual>

    <collision>
      <origin xyz="0 0 0.019" rpy="0 0 0"/>
      <geometry>
        <mesh filename="package://open_manipulator_6dof_description/meshes/chain_link5.stl" scale="0.001 0.001 0.001"/>
      </geometry>
    </collision>

    <inertial>
      <origin xyz="0 0 0" />
      <mass value="0.098" />
      <inertia ixx="0.1" ixy="0.0" ixz="0.0"
               iyy="0.1" iyz="0.0"
               izz="0.1" />
    </inertial>
  </link>

   <!--  Joint 5 -->
  <joint name="sara_2_joint5" type="revolute">
    <parent link="sara_2_link5"/>
    <child link="sara_2_link6"/>
    <origin xyz="0.0 0.0 0.0595" rpy="0 0 0"/>
    <axis xyz="0 1 0"/>
    <limit velocity="4.8" effort="1" lower="${-pi*0.63}" upper="${pi*0.67}" />
  </joint>

  <!--  Link 6 -->
  <link name="sara_2_link6">
    <visual>
      <origin xyz="0 0 0.0" rpy="0 0 0"/>
      <geometry>
        <mesh filename="package://open_manipulator_6dof_description/meshes/chain_link6.stl" scale="0.001 0.001 0.001"/>
      </geometry>
      <material name="grey"/>
    </visual>

    <collision>
      <origin xyz="0 0 0.0" rpy="0 0 0"/>
      <geometry>
        <mesh filename="package://open_manipulator_6dof_description/meshes/chain_link6.stl" scale="0.001 0.001 0.001"/>
      </geometry>
    </collision>

    <inertial>
      <origin xyz="0 0 0" />
      <mass value="0.033" />
      <inertia ixx="0.1" ixy="0.0" ixz="0.0"
               iyy="0.1" iyz="0.0"
               izz="0.1" />
    </inertial>

     <inertial>
      <origin xyz="4.4206755e-02 3.6839985e-07 8.9142216e-03" />
      <mass value="1.4327573e-01" />
      <inertia ixx="8.0870749e-05" ixy="0.0" ixz="-1.0157896e-06"
               iyy="7.5980465e-05" iyz="0.0"
               izz="9.3127351e-05" />
    </inertial>
  </link>

<!--  Joint 6 -->
  <joint name="sara_2_joint6" type="revolute">
    <parent link="sara_2_link6"/>
    <child link="sara_2_link7"/>
    <origin xyz="0.0 0.0 0.0475" rpy="0 0 0"/>
    <axis xyz="0 0 1"/>
    <limit velocity="4.8" effort="1" lower="${-pi*0.9}" upper="${pi*0.9}" />
  </joint>

<!--  Link 7 -->
  <link name="sara_2_link7">
    <visual>
      <origin xyz="0 0 0.0" rpy="0 0 0"/>
      <geometry>
        <mesh filename="package://open_manipulator_6dof_description/meshes/chain_link7.stl" scale="0.001 0.001 0.001"/>
      </geometry>
      <!-- <material name="grey"/> -->
    </visual>

    <collision>
      <origin xyz="0 0 0.0" rpy="0 0 0"/>
      <geometry>
        <mesh filename="package://open_manipulator_6dof_description/meshes/chain_link7.stl" scale="0.001 0.001 0.001"/>
      </geometry>
    </collision>

    <inertial>
      <origin xyz="4.4206755e-02 3.6839985e-07 8.9142216e-03" />
      <mass value="1.4327573e-01" />
      <inertia ixx="8.0870749e-05" ixy="0.0" ixz="-1.0157896e-06"
               iyy="7.5980465e-05" iyz="0.0"
               izz="9.3127351e-05" />
    </inertial>
  </link>

  <!--  Gripper link -->
  <link name="sara_2_gripper_link">
    <visual>
      <origin xyz="0.0 0.0 0" rpy="0 0 0"/>
      <geometry>
        <mesh filename="package://open_manipulator_6dof_description/meshes/chain_link_grip_l.stl" scale="0.001 0.001 0.001"/>
      </geometry>
      <material name="grey"/>
    </visual>

    <collision>
      <origin xyz="0.0 0.0 0" rpy="0 0 0"/>
      <geometry>
        <mesh filename="package://open_manipulator_6dof_description/meshes/chain_link_grip_l.stl" scale="0.001 0.001 0.001"/>
      </geometry>
    </collision>

    <inertial>
      <origin xyz="0 0 0" />
      <mass value="1.0e-03" />
      <inertia ixx="1.0e-03" ixy="0.0" ixz="0.0"
               iyy="1.0e-03" iyz="0.0"
               izz="1.0e-03" />
    </inertial>
  </link>

  <!--  Gripper joint -->
  <joint name="sara_2_gripper" type="prismatic">
    <parent link="sara_2_link7"/>
    <child link="sara_2_gripper_link"/>
    <origin xyz="0.0 0.021 0.0707" rpy="0 0 0"/>
    <axis xyz="0 1 0"/>
    <limit velocity="4.8" effort="1" lower="-0.010" upper="0.019" />
  </joint>

  <!--  Gripper link sub -->
  <link name="sara_2_gripper_link_sub">
    <visual>
      <origin xyz="0.0 -0.0 0" rpy="0 0 0"/>
      <geometry>
        <mesh filename="package://open_manipulator_6dof_description/meshes/chain_link_grip_r.stl" scale="0.001 0.001 0.001"/>
      </geometry>
      <material name="grey"/>
    </visual>

    <collision>
      <origin xyz="0.0 -0.0 0" rpy="0 0 0"/>
      <geometry>
        <mesh filename="package://open_manipulator_6dof_description/meshes/chain_link_grip_r.stl" scale="0.001 0.001 0.001"/>
      </geometry>
    </collision>

    <inertial>
      <origin xyz="0 0 0" />
      <mass value="1.0e-03" />
      <inertia ixx="1.0e-03" ixy="0.0" ixz="0.0"
               iyy="1.0e-03" iyz="0.0"
               izz="1.0e-03" />
    </inertial>
  </link>

  <!--  Gripper joint sub -->
  <joint name="sara_2_gripper_sub" type="prismatic">
    <parent link="sara_2_link7"/>
    <child link="sara_2_gripper_link_sub"/>
    <origin xyz="0.0 -0.021 0.0707" rpy="0 0 0"/>
    <axis xyz="0 -1 0"/>
    <limit velocity="4.8" effort="1" lower="-0.010" upper="0.019" />
    <mimic joint="sara_1_gripper" multiplier="1"/>
  </joint>

  <!-- end effector joint -->
  <joint name="sara_2_end_effector_joint" type="fixed">
    <origin xyz="0.0 0.0 0.115" rpy="0 0 0"/>
    <parent link="sara_1_link7"/>
    <child link="sara_1_end_effector_link"/>
  </joint>

  <!-- end effector link -->
  <link name="sara_2_end_effector_link">
    <visual>
      <origin xyz="0 0 0" rpy="0 0 0"/>
      <geometry>
        <box size="0.01 0.01 0.01" />
      </geometry>
      <material name="red"/>
     </visual>

    <inertial>
      <origin xyz="0 0 0" />
      <mass value="1.0e-03" />
      <inertia ixx="1.0e-03" ixy="0.0" ixz="0.0"
               iyy="1.0e-03" iyz="0.0"
               izz="1.0e-03" />
    </inertial>
  </link>

    <!-- sara_1 arm joints control interface -->
<xacro:SimpleTransmissionPosition n="1" joint="$(arg arm_id_1)_joint1" />
<xacro:SimpleTransmissionPosition n="2" joint="$(arg arm_id_1)_joint2" />
<xacro:SimpleTransmissionPosition n="3" joint="$(arg arm_id_1)_joint3" />
<xacro:SimpleTransmissionPosition n="4" joint="$(arg arm_id_1)_joint4" />
<xacro:SimpleTransmissionPosition n="5" joint="$(arg arm_id_1)_joint5" />
<xacro:SimpleTransmissionPosition n="6" joint="$(arg arm_id_1)_joint6" />
<xacro:SimpleTransmissionPosition n="7" joint="$(arg arm_id_1)_joint7" />

<!-- sara_2 arm joints control interface -->
<xacro:SimpleTransmissionPosition n="8" joint="$(arg arm_id_2)_joint1" />
<xacro:SimpleTransmissionPosition n="9" joint="$(arg arm_id_2)_joint2" />
<xacro:SimpleTransmissionPosition n="10" joint="$(arg arm_id_2)_joint3" />
<xacro:SimpleTransmissionPosition n="11" joint="$(arg arm_id_2)_joint4" />
<xacro:SimpleTransmissionPosition n="12" joint="$(arg arm_id_2)_joint5" />
<xacro:SimpleTransmissionPosition n="13" joint="$(arg arm_id_2)_joint6" />
<xacro:SimpleTransmissionPosition n="14" joint="$(arg arm_id_2)_joint7" />

<!-- sara_1 gripper joints control interface -->
<xacro:SimpleTransmissionEffort n="15" joint="$(arg arm_id_1)_Gripper_link" />
<xacro:SimpleTransmissionEffort n="16" joint="$(arg arm_id_1)_Gripper_joint" />
<xacro:SimpleTransmissionEffort n="17" joint="$(arg arm_id_1)_Gripper_link_sub" />
<xacro:SimpleTransmissionEffort n="18" joint="$(arg arm_id_1)_Gripper_joint_sub" />
<xacro:SimpleTransmissionEffort n="19" joint="$(arg arm_id_1)_end_effector_joint" />
<xacro:SimpleTransmissionEffort n="20" joint="$(arg arm_id_1)_end_effector_link" />

<!-- sara_2 gripper joints control interface -->
<xacro:SimpleTransmissionEffort n="21" joint="$(arg arm_id_2)_Gripper_link" />
<xacro:SimpleTransmissionEffort n="22" joint="$(arg arm_id_2)_Gripper_joint" />
<xacro:SimpleTransmissionEffort n="23" joint="$(arg arm_id_2)_Gripper_link_sub" />
<xacro:SimpleTransmissionEffort n="24" joint="$(arg arm_id_2)_Gripper_joint_sub" />
<xacro:SimpleTransmissionEffort n="25" joint="$(arg arm_id_2)_end_effector_joint" />
<xacro:SimpleTransmissionEffort n="26" joint="$(arg arm_id_2)_end_effector_link" />


    <!-- load ros_control plugin -->
    <gazebo>
        <plugin name="gazebo_ros_control" filename="libgazebo_ros_control.so"/>
    </gazebo>

</robot>